<?xml version="1.0" ?>
<robot name="disk" xmlns:xacro="http://www.ros.org/wiki/xacro">
<!--<xacro:include filename="$(find m2wr_description)/urdf/materials.xacro" />-->
<!--<xacro:include filename="$(find self_balancing_robot)/urdf/denge.gazebo" />-->

<!-- şase  -->
  <link name="link_chassis">
    <!-- pose and inertial -->
    <pose>0 0 0.1 0 0 0</pose>
    <inertial>
      <mass value="0.5"/>
      <origin rpy="0 0 0" xyz="0 0 0"/>
      <inertia ixx="0.002786458333" ixy="0" ixz="0" iyy="0.002786458333" iyz="0" izz="0.00390625"/>
    </inertial>
    <!-- body -->
    <collision name="collision_chassis">
    <origin xyz="0 0 0" rpy="0 0 0"/>
      <geometry>
        <cylinder radius="0.100" length="0.02"/>
      </geometry>
    </collision>
    <visual>
      <origin rpy="0 0 0" xyz="0 0 0"/>
      <geometry>
        <cylinder radius="0.100" length="0.02"/>
      </geometry>
      <material name= "red"/>
    </visual>
</link>

<!--sol tekerlek --> 

<link name="link_left_wheel">
    <inertial>
      <mass value="0.25"/>
      <origin rpy="0 1.5707 1.5707" xyz="0 0 0"/>
      <inertia ixx="0.00015" ixy="0" ixz="0" iyy="0.00015" iyz="0" izz="0.0003125"/>
    </inertial>
    <collision name="link_left_wheel_collision">
     <origin rpy="0 1.5707 1.5707" xyz="0 0 0"/>
      <geometry>
       <cylinder length="0.008" radius="0.05"/>
      </geometry>
    </collision>
    <visual name="link_left_wheel_visual">
      <origin rpy="0 1.5707 1.5707" xyz="0 0 0"/>
      <geometry>
        <cylinder length="0.008" radius="0.05"/>
      </geometry>
    </visual>
  </link>
  
  <joint name="joint_left_wheel" type="continuous">
    <origin rpy="0 0 0" xyz="0 -0.1 0"/>
    <child link="link_left_wheel"/>
    <parent link="link_chassis"/>
    <axis rpy="0 0 0" xyz="0 1 0"/>
    <limit effort="10000" velocity="1000"/>
    <joint_properties damping="1.0" friction="1.0"/>
</joint>

<!--sağ tekerlek--> 

<link name="link_right_wheel">
    <inertial>
      <mass value="0.25"/>
      <origin rpy="0 1.5707 1.5707" xyz="0 0 0"/>
      <inertia ixx="0.00015" ixy="0" ixz="0" iyy="0.00015" iyz="0" izz="0.0003125"/>
    </inertial>
    <collision name="link_right_wheel_collision">
      <origin rpy="0 1.5707 1.5707" xyz="0 0 0"/>
      <geometry>
        <cylinder length="0.008" radius="0.05"/>
      </geometry>
    </collision>
    <visual name="link_right_wheel_visual">
      <origin rpy="0 1.5707 1.5707" xyz="0 0 0"/>
      <geometry>
        <cylinder length="0.008" radius="0.05"/>
      </geometry>
    </visual>
  </link>
  
  <joint name="joint_right_wheel" type="continuous">
    <origin rpy="0 0 0" xyz="0 0.1 0"/>
    <child link="link_right_wheel"/>
    <parent link="link_chassis"/>
    <axis rpy="0 0 0" xyz="0 1 0"/>
    <limit effort="10000" velocity="1000"/>
    <joint_properties damping="1.0" friction="1.0"/>
</joint>


  <gazebo>
    <plugin filename="libgazebo_ros_diff_drive.so" name="differential_drive_controller">
      <legacyMode>false</legacyMode>
      <alwaysOn>true</alwaysOn>
      <updateRate>20</updateRate>
      <leftJoint>joint_left_wheel</leftJoint>
      <rightJoint>joint_right_wheel</rightJoint>
      <wheelSeparation>0.2</wheelSeparation>
      <wheelDiameter>0.2</wheelDiameter>
      <torque>20</torque>
      <commandTopic>cmd_vel</commandTopic>
      <odometryTopic>odom</odometryTopic>
      <odometryFrame>odom</odometryFrame>
      <robotBaseFrame>link_chassis</robotBaseFrame>
    </plugin>
    </gazebo>

  <gazebo reference="link_chassis">
    <material>Gazebo/Black</material>
  </gazebo>

  <gazebo reference="link_left_wheel">
    <material>Gazebo/White</material>
  </gazebo>

  <gazebo reference="link_right_wheel">
    <material>Gazebo/White</material>
  </gazebo>

</robot>